<?xml version="1.0"?>
<robot xmlns:xacro="http://www.ros.org/wiki/xacro" name="mybot">

    <xacro:include filename="inertial_macros.xacro" />

    <!-- MATERIALS -->
    <material name="white"><color rgba="1 1 1 1"/></material>
    <material name="orange"><color rgba="1 0.3 0.1 1"/></material>
    <material name="blue"><color rgba="0.2 0.2 1 1"/></material>
    <material name="black"><color rgba="0 0 0 1"/></material>
    <material name="red"><color rgba="1 0 0 1"/></material>

    <!-- BASE LINK -->
    <link name="base_link"/>

    <!-- CHASSIS LINK -->
    <joint name="chassis_joint" type="fixed">
        <parent link="base_link"/>
        <child link="chassis"/>
        <origin xyz="-0.1 0 0"/>
    </joint>

    <link name="chassis">
        <visual>
            <origin xyz="0.15 0 0.075"/>
            <geometry>
                <box size="0.3 0.3 0.15"/>
            </geometry>
            <material name="white"/>
        </visual>
        <collision>
            <origin xyz="0.15 0 0.075"/>
            <geometry>
                <box size="0.3 0.3 0.15"/>
            </geometry>
        </collision>
        <xacro:inertial_box mass="0.5" x="0.3" y="0.3" z="0.15"/>
    </link>

    <gazebo reference="chassis">
        <visual>
            <material>
                <ambient>1 1 1 1</ambient>
                <diffuse>1 1 1 1</diffuse>
                <specular>1 1 1 1</specular>
            </material>
        </visual>
    </gazebo>

    <!-- LEFT WHEEL -->
    <joint name="left_wheel_joint" type="continuous">
        <parent link="base_link"/>
        <child link="left_wheel"/>
        <origin xyz="0 0.175 0" rpy="-${pi/2} 0 0"/>
        <axis xyz="0 0 1"/>
    </joint>

    <link name="left_wheel">
        <visual>
            <geometry>
                <cylinder length="0.04" radius="0.05"/>
            </geometry>
            <material name="blue"/>
        </visual>
        <collision>
            <geometry>
                <cylinder length="0.04" radius="0.05"/>
            </geometry>
        </collision>
        <xacro:inertial_cylinder mass="0.1" length="0.04" radius="0.05"/>
    </link>

    <gazebo reference="left_wheel">
        <visual>
            <material>
                <ambient>0.2 0.2 1 1</ambient>
                <diffuse>0.2 0.2 1 1</diffuse>
                <specular>0.2 0.2 1 1</specular>
            </material>
        </visual>
        <!-- ADDED FRICTION FOR LEFT WHEEL -->
        <collision>
            <surface>
                <friction>
                    <ode>
                        <mu>1.0</mu>        <!-- High friction for driving -->
                        <mu2>1.0</mu2>      <!-- High friction for driving -->
                        <slip1>0.0</slip1> <!-- Small amount of slip for realism -->
                        <slip2>0.0</slip2>
                    </ode>
                </friction>
            </surface>
        </collision>
    </gazebo>

    <!-- RIGHT WHEEL -->
    <joint name="right_wheel_joint" type="continuous">
        <parent link="base_link"/>
        <child link="right_wheel"/>
        <origin xyz="0 -0.175 0" rpy="${pi/2} 0 0"/>
        <axis xyz="0 0 -1"/> 
    </joint>

    <link name="right_wheel">
        <visual>
            <geometry>
                <cylinder length="0.04" radius="0.05"/>
            </geometry>
            <material name="blue"/>
        </visual>
        <collision>
            <geometry>
                <cylinder length="0.04" radius="0.05"/>
            </geometry>
        </collision>
        <xacro:inertial_cylinder mass="0.1" length="0.04" radius="0.05"/>
    </link>

    <gazebo reference="right_wheel">
        <visual>
            <material>
                <ambient>0.2 0.2 1 1</ambient>
                <diffuse>0.2 0.2 1 1</diffuse>
                <specular>0.2 0.2 1 1</specular>
            </material>
        </visual>
        <!-- ADDED FRICTION FOR RIGHT WHEEL -->
        <collision>
            <surface>
                <friction>
                    <ode>
                        <mu>1.0</mu>        <!-- High friction for driving -->
                        <mu2>1.0</mu2>      <!-- High friction for driving -->
                        <slip1>0.0</slip1> <!-- Small amount of slip for realism -->
                        <slip2>0.0</slip2>
                    </ode>
                </friction>
            </surface>
        </collision>
    </gazebo>

    <!-- CASTER WHEEL -->
    <joint name="caster_wheel_joint" type="fixed">
        <parent link="chassis"/>
        <child link="caster_wheel"/>
        <origin xyz="0.24 0 0"/>
    </joint>

    <link name="caster_wheel">
        <visual>
            <geometry>
                <sphere radius="0.05"/>
            </geometry>
            <material name="black"/>
        </visual>
        <collision>
            <geometry>
                <sphere radius="0.05"/>
            </geometry>
        </collision>
        <xacro:inertial_sphere mass="0.1" radius="0.05"/>
    </link>

    <gazebo reference="caster_wheel">
        <visual>
            <material>
                <ambient>0 0 0 1</ambient>
                <diffuse>0 0 0 1</diffuse>
                <specular>0 0 0 1</specular>
            </material>
        </visual>
        <collision>
            <surface>
                <friction>
                    <ode>
                        <mu>0.01</mu>
                        <mu2>0.01</mu2>
                    </ode>
                </friction>
            </surface>
        </collision>
    </gazebo>
    
    <gazebo>
        <!-- Diff Drive Plugin -->
        <plugin filename="libignition-gazebo-diff-drive-system.so" name="ignition::gazebo::systems::DiffDrive">
            
            <left_joint>left_wheel_joint</left_joint>
            <right_joint>right_wheel_joint</right_joint>
            
            <!-- Kinematics based on your link geometry -->
            <wheel_separation>0.35</wheel_separation>
            <wheel_radius>0.05</wheel_radius>

            <!-- Limits -->
            <max_linear_acceleration>1</max_linear_acceleration>
            <min_linear_acceleration>-1</min_linear_acceleration>
            <max_angular_acceleration>2</max_angular_acceleration>
            <min_angular_acceleration>-2</min_angular_acceleration>
            <max_linear_velocity>0.5</max_linear_velocity>
            <min_linear_velocity>-0.5</min_linear_velocity>
            <max_angular_velocity>1</max_angular_velocity>
            <min_angular_velocity>-1</min_angular_velocity>

            <!-- Output Topics -->
            <topic>cmd_vel</topic>
            <odom_topic>odom</odom_topic>
            <tf_topic>tf</tf_topic>
            <frame_id>odom</frame_id>
            <child_frame_id>base_link</child_frame_id>
            <odom_publisher_frequency>30</odom_publisher_frequency>
        </plugin>
        
        <!-- Joint State Publisher (Publishes TFs for wheels) -->
        <plugin filename="libignition-gazebo-joint-state-publisher-system.so" name="ignition::gazebo::systems::JointStatePublisher">
            <topic>joint_states</topic>
            <joint_name>left_wheel_joint</joint_name>
            <joint_name>right_wheel_joint</joint_name>
        </plugin>
    </gazebo>

</robot>